Vocabulary size: 43405
Traceback (most recent call last):
  File "/home/yoshioka20/nas02home/TG/CVAE-t-CWS/reconstract.py", line 384, in <module>
    main(args)
  File "/home/yoshioka20/nas02home/TG/CVAE-t-CWS/reconstract.py", line 130, in main
    model = attnVAE(**kwargs)
TypeError: __init__() missing 1 required positional argument: 'debug'
Vocabulary size: 43405
Traceback (most recent call last):
  File "/home/yoshioka20/nas02home/TG/CVAE-t-CWS/reconstract.py", line 384, in <module>
    main(args)
  File "/home/yoshioka20/nas02home/TG/CVAE-t-CWS/reconstract.py", line 130, in main
    model = attnVAE(**kwargs)
TypeError: __init__() missing 1 required positional argument: 'debug'
Traceback (most recent call last):
  File "/home/yoshioka20/nas02home/TG/CVAE-t-CWS/evaluate.py", line 354, in <module>
    main(args)
  File "/home/yoshioka20/nas02home/TG/CVAE-t-CWS/evaluate.py", line 117, in main
    eval_data = MonoTextData(target_pth, True, vocab=vocab, b_vocab=b_vocab)
  File "/nas02/homes/yoshioka20-1000032/TG/CVAE-t-CWS/utils/text_utils.py", line 143, in __init__
    ) = self._read_corpus(fname, label, max_length, vocab, b_vocab, ft)
  File "/nas02/homes/yoshioka20-1000032/TG/CVAE-t-CWS/utils/text_utils.py", line 156, in _read_corpus
    with open(fname) as fin:
FileNotFoundError: [Errno 2] No such file or directory: 'checkpoint/ours-jsw-attn+pe/20231027-170745/reconstracted_results.txt'
Traceback (most recent call last):
  File "/home/yoshioka20/nas02home/TG/CVAE-t-CWS/evaluate.py", line 354, in <module>
    main(args)
  File "/home/yoshioka20/nas02home/TG/CVAE-t-CWS/evaluate.py", line 117, in main
    eval_data = MonoTextData(target_pth, True, vocab=vocab, b_vocab=b_vocab)
  File "/nas02/homes/yoshioka20-1000032/TG/CVAE-t-CWS/utils/text_utils.py", line 143, in __init__
    ) = self._read_corpus(fname, label, max_length, vocab, b_vocab, ft)
  File "/nas02/homes/yoshioka20-1000032/TG/CVAE-t-CWS/utils/text_utils.py", line 156, in _read_corpus
    with open(fname) as fin:
FileNotFoundError: [Errno 2] No such file or directory: 'checkpoint/ours-jsw-attn+pe/20231027-170745/transfer_results.txt'
Traceback (most recent call last):
  File "/home/yoshioka20/nas02home/TG/CVAE-t-CWS/recon_to_pos.py", line 222, in <module>
    main(args)
  File "/home/yoshioka20/nas02home/TG/CVAE-t-CWS/recon_to_pos.py", line 92, in main
    with open(path, "r") as fin, open(
FileNotFoundError: [Errno 2] No such file or directory: 'checkpoint/ours-jsw-attn+pe/20231027-170745/transfer_results.txt'
Traceback (most recent call last):
  File "/home/yoshioka20/nas02home/TG/CVAE-t-CWS/recon_to_pos.py", line 222, in <module>
    main(args)
  File "/home/yoshioka20/nas02home/TG/CVAE-t-CWS/recon_to_pos.py", line 92, in main
    with open(path, "r") as fin, open(
FileNotFoundError: [Errno 2] No such file or directory: 'checkpoint/ours-jsw-attn+pe/20231027-170745/transfer_results.txt'
Traceback (most recent call last):
  File "/home/yoshioka20/nas02home/TG/CVAE-t-CWS/evaluate.py", line 354, in <module>
    main(args)
  File "/home/yoshioka20/nas02home/TG/CVAE-t-CWS/evaluate.py", line 126, in main
    eval_data = MonoTextData(
  File "/nas02/homes/yoshioka20-1000032/TG/CVAE-t-CWS/utils/text_utils.py", line 143, in __init__
    ) = self._read_corpus(fname, label, max_length, vocab, b_vocab, ft)
  File "/nas02/homes/yoshioka20-1000032/TG/CVAE-t-CWS/utils/text_utils.py", line 156, in _read_corpus
    with open(fname) as fin:
FileNotFoundError: [Errno 2] No such file or directory: 'checkpoint/ours-jsw-attn+pe/20231027-170745/transfer_results0_1.txt'
Traceback (most recent call last):
  File "/home/yoshioka20/nas02home/TG/CVAE-t-CWS/evaluate.py", line 354, in <module>
    main(args)
  File "/home/yoshioka20/nas02home/TG/CVAE-t-CWS/evaluate.py", line 119, in main
    eval_data = MonoTextData(
  File "/nas02/homes/yoshioka20-1000032/TG/CVAE-t-CWS/utils/text_utils.py", line 143, in __init__
    ) = self._read_corpus(fname, label, max_length, vocab, b_vocab, ft)
  File "/nas02/homes/yoshioka20-1000032/TG/CVAE-t-CWS/utils/text_utils.py", line 156, in _read_corpus
    with open(fname) as fin:
FileNotFoundError: [Errno 2] No such file or directory: 'checkpoint/ours-jsw-attn+pe/20231027-170745/transfer_results1_0.txt'
Vocabulary size: 43405
Traceback (most recent call last):
  File "/home/yoshioka20/nas02home/TG/CVAE-t-CWS/reconstract.py", line 384, in <module>
    main(args)
  File "/home/yoshioka20/nas02home/TG/CVAE-t-CWS/reconstract.py", line 130, in main
    model = attnVAE(**kwargs)
TypeError: __init__() missing 1 required positional argument: 'debug'
Vocabulary size: 43405
Traceback (most recent call last):
  File "/home/yoshioka20/nas02home/TG/CVAE-t-CWS/reconstract.py", line 384, in <module>
    main(args)
  File "/home/yoshioka20/nas02home/TG/CVAE-t-CWS/reconstract.py", line 130, in main
    model = attnVAE(**kwargs)
TypeError: __init__() missing 1 required positional argument: 'debug'
